[2024-09-22T23:49:12.602+0000] {local_task_job_runner.py:123} INFO - ::group::Pre task execution logs
[2024-09-22T23:49:12.627+0000] {taskinstance.py:2612} INFO - Dependencies all met for dep_context=non-requeueable deps ti=<TaskInstance: fastapi_communication_dag.fastapi_communication_task scheduled__2023-01-01T00:00:00+00:00 [queued]>
[2024-09-22T23:49:12.636+0000] {taskinstance.py:2612} INFO - Dependencies all met for dep_context=requeueable deps ti=<TaskInstance: fastapi_communication_dag.fastapi_communication_task scheduled__2023-01-01T00:00:00+00:00 [queued]>
[2024-09-22T23:49:12.637+0000] {taskinstance.py:2865} INFO - Starting attempt 1 of 1
[2024-09-22T23:49:12.652+0000] {taskinstance.py:2888} INFO - Executing <Task(PythonOperator): fastapi_communication_task> on 2023-01-01 00:00:00+00:00
[2024-09-22T23:49:12.664+0000] {warnings.py:112} WARNING - /home/***/.local/lib/python3.12/site-packages/***/task/task_runner/standard_task_runner.py:70: DeprecationWarning: This process (pid=86) is multi-threaded, use of fork() may lead to deadlocks in the child.
  pid = os.fork()

[2024-09-22T23:49:12.666+0000] {standard_task_runner.py:72} INFO - Started process 89 to run task
[2024-09-22T23:49:12.668+0000] {standard_task_runner.py:104} INFO - Running: ['***', 'tasks', 'run', 'fastapi_communication_dag', 'fastapi_communication_task', 'scheduled__2023-01-01T00:00:00+00:00', '--job-id', '5', '--raw', '--subdir', 'DAGS_FOLDER/fast_api_comms.py', '--cfg-path', '/tmp/tmpii8ulqh0']
[2024-09-22T23:49:12.669+0000] {standard_task_runner.py:105} INFO - Job 5: Subtask fastapi_communication_task
[2024-09-22T23:49:12.738+0000] {task_command.py:467} INFO - Running <TaskInstance: fastapi_communication_dag.fastapi_communication_task scheduled__2023-01-01T00:00:00+00:00 [running]> on host 389d64706566
[2024-09-22T23:49:12.850+0000] {taskinstance.py:3131} INFO - Exporting env vars: AIRFLOW_CTX_DAG_OWNER='***' AIRFLOW_CTX_DAG_ID='fastapi_communication_dag' AIRFLOW_CTX_TASK_ID='fastapi_communication_task' AIRFLOW_CTX_EXECUTION_DATE='2023-01-01T00:00:00+00:00' AIRFLOW_CTX_TRY_NUMBER='1' AIRFLOW_CTX_DAG_RUN_ID='scheduled__2023-01-01T00:00:00+00:00'
[2024-09-22T23:49:12.852+0000] {logging_mixin.py:190} INFO - Task instance is in running state
[2024-09-22T23:49:12.852+0000] {logging_mixin.py:190} INFO -  Previous state of the Task instance: queued
[2024-09-22T23:49:12.852+0000] {logging_mixin.py:190} INFO - Current task name:fastapi_communication_task state:running start_date:2024-09-22 23:49:12.627581+00:00
[2024-09-22T23:49:12.853+0000] {logging_mixin.py:190} INFO - Dag name:fastapi_communication_dag and current dag run status:running
[2024-09-22T23:49:12.853+0000] {taskinstance.py:731} INFO - ::endgroup::
[2024-09-22T23:49:12.864+0000] {logging_mixin.py:190} INFO - Falha na comunicação. Status Code: 404
[2024-09-22T23:49:12.865+0000] {logging_mixin.py:190} INFO - Falha na comunicação com app_fastapi.
[2024-09-22T23:49:12.865+0000] {taskinstance.py:3310} ERROR - Task failed with exception
Traceback (most recent call last):
  File "/home/airflow/.local/lib/python3.12/site-packages/airflow/models/taskinstance.py", line 767, in _execute_task
    result = _execute_callable(context=context, **execute_callable_kwargs)
             ^^^^^^^^^^^^^^^^^^^^^^^^^^^^^^^^^^^^^^^^^^^^^^^^^^^^^^^^^^^^^
  File "/home/airflow/.local/lib/python3.12/site-packages/airflow/models/taskinstance.py", line 733, in _execute_callable
    return ExecutionCallableRunner(
           ^^^^^^^^^^^^^^^^^^^^^^^^
  File "/home/airflow/.local/lib/python3.12/site-packages/airflow/utils/operator_helpers.py", line 252, in run
    return self.func(*args, **kwargs)
           ^^^^^^^^^^^^^^^^^^^^^^^^^^
  File "/home/airflow/.local/lib/python3.12/site-packages/airflow/models/baseoperator.py", line 406, in wrapper
    return func(self, *args, **kwargs)
           ^^^^^^^^^^^^^^^^^^^^^^^^^^^
  File "/home/airflow/.local/lib/python3.12/site-packages/airflow/operators/python.py", line 238, in execute
    return_value = self.execute_callable()
                   ^^^^^^^^^^^^^^^^^^^^^^^
  File "/home/airflow/.local/lib/python3.12/site-packages/airflow/operators/python.py", line 256, in execute_callable
    return runner.run(*self.op_args, **self.op_kwargs)
           ^^^^^^^^^^^^^^^^^^^^^^^^^^^^^^^^^^^^^^^^^^^
  File "/home/airflow/.local/lib/python3.12/site-packages/airflow/utils/operator_helpers.py", line 252, in run
    return self.func(*args, **kwargs)
           ^^^^^^^^^^^^^^^^^^^^^^^^^^
  File "/opt/airflow/dags/fast_api_comms.py", line 13, in test_communication
    raise Exception("Falha na comunicação com app_fastapi.")
Exception: Falha na comunicação com app_fastapi.
[2024-09-22T23:49:12.878+0000] {logging_mixin.py:190} INFO - Task instance in failure state
[2024-09-22T23:49:12.879+0000] {logging_mixin.py:190} INFO - Task start:2024-09-22 23:49:12.627581+00:00 end:2024-09-22 23:49:12.877823+00:00 duration:0.250242
[2024-09-22T23:49:12.879+0000] {logging_mixin.py:190} INFO - Task:<Task(PythonOperator): fastapi_communication_task> dag:<DAG: fastapi_communication_dag> dagrun:<DagRun fastapi_communication_dag @ 2023-01-01 00:00:00+00:00: scheduled__2023-01-01T00:00:00+00:00, state:running, queued_at: 2024-09-22 23:49:07.877623+00:00. externally triggered: False>
[2024-09-22T23:49:12.879+0000] {logging_mixin.py:190} INFO - Failure caused by Falha na comunicação com app_fastapi.
[2024-09-22T23:49:12.880+0000] {taskinstance.py:1225} INFO - Marking task as FAILED. dag_id=fastapi_communication_dag, task_id=fastapi_communication_task, run_id=scheduled__2023-01-01T00:00:00+00:00, execution_date=20230101T000000, start_date=20240922T234912, end_date=20240922T234912
[2024-09-22T23:49:12.897+0000] {taskinstance.py:340} INFO - ::group::Post task execution logs
[2024-09-22T23:49:12.898+0000] {standard_task_runner.py:124} ERROR - Failed to execute job 5 for task fastapi_communication_task (Falha na comunicação com app_fastapi.; 89)
Traceback (most recent call last):
  File "/home/airflow/.local/lib/python3.12/site-packages/airflow/task/task_runner/standard_task_runner.py", line 117, in _start_by_fork
    ret = args.func(args, dag=self.dag)
          ^^^^^^^^^^^^^^^^^^^^^^^^^^^^^
  File "/home/airflow/.local/lib/python3.12/site-packages/airflow/cli/cli_config.py", line 49, in command
    return func(*args, **kwargs)
           ^^^^^^^^^^^^^^^^^^^^^
  File "/home/airflow/.local/lib/python3.12/site-packages/airflow/utils/cli.py", line 115, in wrapper
    return f(*args, **kwargs)
           ^^^^^^^^^^^^^^^^^^
  File "/home/airflow/.local/lib/python3.12/site-packages/airflow/cli/commands/task_command.py", line 483, in task_run
    task_return_code = _run_task_by_selected_method(args, _dag, ti)
                       ^^^^^^^^^^^^^^^^^^^^^^^^^^^^^^^^^^^^^^^^^^^^
  File "/home/airflow/.local/lib/python3.12/site-packages/airflow/cli/commands/task_command.py", line 256, in _run_task_by_selected_method
    return _run_raw_task(args, ti)
           ^^^^^^^^^^^^^^^^^^^^^^^
  File "/home/airflow/.local/lib/python3.12/site-packages/airflow/cli/commands/task_command.py", line 341, in _run_raw_task
    return ti._run_raw_task(
           ^^^^^^^^^^^^^^^^^
  File "/home/airflow/.local/lib/python3.12/site-packages/airflow/utils/session.py", line 97, in wrapper
    return func(*args, session=session, **kwargs)
           ^^^^^^^^^^^^^^^^^^^^^^^^^^^^^^^^^^^^^^
  File "/home/airflow/.local/lib/python3.12/site-packages/airflow/models/taskinstance.py", line 3004, in _run_raw_task
    return _run_raw_task(
           ^^^^^^^^^^^^^^
  File "/home/airflow/.local/lib/python3.12/site-packages/airflow/models/taskinstance.py", line 273, in _run_raw_task
    TaskInstance._execute_task_with_callbacks(
  File "/home/airflow/.local/lib/python3.12/site-packages/airflow/models/taskinstance.py", line 3158, in _execute_task_with_callbacks
    result = self._execute_task(context, task_orig)
             ^^^^^^^^^^^^^^^^^^^^^^^^^^^^^^^^^^^^^^
  File "/home/airflow/.local/lib/python3.12/site-packages/airflow/models/taskinstance.py", line 3182, in _execute_task
    return _execute_task(self, context, task_orig)
           ^^^^^^^^^^^^^^^^^^^^^^^^^^^^^^^^^^^^^^^
  File "/home/airflow/.local/lib/python3.12/site-packages/airflow/models/taskinstance.py", line 767, in _execute_task
    result = _execute_callable(context=context, **execute_callable_kwargs)
             ^^^^^^^^^^^^^^^^^^^^^^^^^^^^^^^^^^^^^^^^^^^^^^^^^^^^^^^^^^^^^
  File "/home/airflow/.local/lib/python3.12/site-packages/airflow/models/taskinstance.py", line 733, in _execute_callable
    return ExecutionCallableRunner(
           ^^^^^^^^^^^^^^^^^^^^^^^^
  File "/home/airflow/.local/lib/python3.12/site-packages/airflow/utils/operator_helpers.py", line 252, in run
    return self.func(*args, **kwargs)
           ^^^^^^^^^^^^^^^^^^^^^^^^^^
  File "/home/airflow/.local/lib/python3.12/site-packages/airflow/models/baseoperator.py", line 406, in wrapper
    return func(self, *args, **kwargs)
           ^^^^^^^^^^^^^^^^^^^^^^^^^^^
  File "/home/airflow/.local/lib/python3.12/site-packages/airflow/operators/python.py", line 238, in execute
    return_value = self.execute_callable()
                   ^^^^^^^^^^^^^^^^^^^^^^^
  File "/home/airflow/.local/lib/python3.12/site-packages/airflow/operators/python.py", line 256, in execute_callable
    return runner.run(*self.op_args, **self.op_kwargs)
           ^^^^^^^^^^^^^^^^^^^^^^^^^^^^^^^^^^^^^^^^^^^
  File "/home/airflow/.local/lib/python3.12/site-packages/airflow/utils/operator_helpers.py", line 252, in run
    return self.func(*args, **kwargs)
           ^^^^^^^^^^^^^^^^^^^^^^^^^^
  File "/opt/airflow/dags/fast_api_comms.py", line 13, in test_communication
    raise Exception("Falha na comunicação com app_fastapi.")
Exception: Falha na comunicação com app_fastapi.
[2024-09-22T23:49:12.922+0000] {local_task_job_runner.py:266} INFO - Task exited with return code 1
[2024-09-22T23:49:12.936+0000] {local_task_job_runner.py:245} INFO - ::endgroup::
